2025-04-12 09:20:26 [INFO] llm: [req_1744413626] Sending LLM request
2025-04-12 09:20:26 [INFO] llm: [req_1744413626] Sending LLM request
2025-04-12 09:20:36 [ERROR] llm: [req_1744413626] LLM service error: [Errno -3] Temporary failure in name resolution
Traceback (most recent call last):
  File "/mnt/c/Users/Andrew/Documents/freegenai/opea-comps-w3/venv/lib/python3.12/site-packages/httpx/_transports/default.py", line 101, in map_httpcore_exceptions
    yield
  File "/mnt/c/Users/Andrew/Documents/freegenai/opea-comps-w3/venv/lib/python3.12/site-packages/httpx/_transports/default.py", line 394, in handle_async_request
    resp = await self._pool.handle_async_request(req)
           ^^^^^^^^^^^^^^^^^^^^^^^^^^^^^^^^^^^^^^^^^^
  File "/mnt/c/Users/Andrew/Documents/freegenai/opea-comps-w3/venv/lib/python3.12/site-packages/httpcore/_async/connection_pool.py", line 256, in handle_async_request
    raise exc from None
  File "/mnt/c/Users/Andrew/Documents/freegenai/opea-comps-w3/venv/lib/python3.12/site-packages/httpcore/_async/connection_pool.py", line 236, in handle_async_request
    response = await connection.handle_async_request(
               ^^^^^^^^^^^^^^^^^^^^^^^^^^^^^^^^^^^^^^
  File "/mnt/c/Users/Andrew/Documents/freegenai/opea-comps-w3/venv/lib/python3.12/site-packages/httpcore/_async/connection.py", line 101, in handle_async_request
    raise exc
  File "/mnt/c/Users/Andrew/Documents/freegenai/opea-comps-w3/venv/lib/python3.12/site-packages/httpcore/_async/connection.py", line 78, in handle_async_request
    stream = await self._connect(request)
             ^^^^^^^^^^^^^^^^^^^^^^^^^^^^
  File "/mnt/c/Users/Andrew/Documents/freegenai/opea-comps-w3/venv/lib/python3.12/site-packages/httpcore/_async/connection.py", line 124, in _connect
    stream = await self._network_backend.connect_tcp(**kwargs)
             ^^^^^^^^^^^^^^^^^^^^^^^^^^^^^^^^^^^^^^^^^^^^^^^^^
  File "/mnt/c/Users/Andrew/Documents/freegenai/opea-comps-w3/venv/lib/python3.12/site-packages/httpcore/_backends/auto.py", line 31, in connect_tcp
    return await self._backend.connect_tcp(
           ^^^^^^^^^^^^^^^^^^^^^^^^^^^^^^^^
  File "/mnt/c/Users/Andrew/Documents/freegenai/opea-comps-w3/venv/lib/python3.12/site-packages/httpcore/_backends/anyio.py", line 113, in connect_tcp
    with map_exceptions(exc_map):
  File "/usr/lib/python3.12/contextlib.py", line 158, in __exit__
    self.gen.throw(value)
  File "/mnt/c/Users/Andrew/Documents/freegenai/opea-comps-w3/venv/lib/python3.12/site-packages/httpcore/_exceptions.py", line 14, in map_exceptions
    raise to_exc(exc) from exc
httpcore.ConnectError: [Errno -3] Temporary failure in name resolution

The above exception was the direct cause of the following exception:

Traceback (most recent call last):
  File "/mnt/c/Users/Andrew/Documents/freegenai/opea-comps-w3/MegaService/server.py", line 313, in megaservice
    llm_response = await llm_client.post(
                   ^^^^^^^^^^^^^^^^^^^^^^
  File "/mnt/c/Users/Andrew/Documents/freegenai/opea-comps-w3/venv/lib/python3.12/site-packages/httpx/_client.py", line 1859, in post
    return await self.request(
           ^^^^^^^^^^^^^^^^^^^
  File "/mnt/c/Users/Andrew/Documents/freegenai/opea-comps-w3/venv/lib/python3.12/site-packages/httpx/_client.py", line 1540, in request
    return await self.send(request, auth=auth, follow_redirects=follow_redirects)
           ^^^^^^^^^^^^^^^^^^^^^^^^^^^^^^^^^^^^^^^^^^^^^^^^^^^^^^^^^^^^^^^^^^^^^^
  File "/mnt/c/Users/Andrew/Documents/freegenai/opea-comps-w3/venv/lib/python3.12/site-packages/httpx/_client.py", line 1629, in send
    response = await self._send_handling_auth(
               ^^^^^^^^^^^^^^^^^^^^^^^^^^^^^^^
  File "/mnt/c/Users/Andrew/Documents/freegenai/opea-comps-w3/venv/lib/python3.12/site-packages/httpx/_client.py", line 1657, in _send_handling_auth
    response = await self._send_handling_redirects(
               ^^^^^^^^^^^^^^^^^^^^^^^^^^^^^^^^^^^^
  File "/mnt/c/Users/Andrew/Documents/freegenai/opea-comps-w3/venv/lib/python3.12/site-packages/httpx/_client.py", line 1694, in _send_handling_redirects
    response = await self._send_single_request(request)
               ^^^^^^^^^^^^^^^^^^^^^^^^^^^^^^^^^^^^^^^^
  File "/mnt/c/Users/Andrew/Documents/freegenai/opea-comps-w3/venv/lib/python3.12/site-packages/httpx/_client.py", line 1730, in _send_single_request
    response = await transport.handle_async_request(request)
               ^^^^^^^^^^^^^^^^^^^^^^^^^^^^^^^^^^^^^^^^^^^^^
  File "/mnt/c/Users/Andrew/Documents/freegenai/opea-comps-w3/venv/lib/python3.12/site-packages/httpx/_transports/default.py", line 393, in handle_async_request
    with map_httpcore_exceptions():
  File "/usr/lib/python3.12/contextlib.py", line 158, in __exit__
    self.gen.throw(value)
  File "/mnt/c/Users/Andrew/Documents/freegenai/opea-comps-w3/venv/lib/python3.12/site-packages/httpx/_transports/default.py", line 118, in map_httpcore_exceptions
    raise mapped_exc(message) from exc
httpx.ConnectError: [Errno -3] Temporary failure in name resolution
2025-04-12 09:20:36 [ERROR] llm: [req_1744413626] LLM service error: [Errno -3] Temporary failure in name resolution
Traceback (most recent call last):
  File "/mnt/c/Users/Andrew/Documents/freegenai/opea-comps-w3/venv/lib/python3.12/site-packages/httpx/_transports/default.py", line 101, in map_httpcore_exceptions
    yield
  File "/mnt/c/Users/Andrew/Documents/freegenai/opea-comps-w3/venv/lib/python3.12/site-packages/httpx/_transports/default.py", line 394, in handle_async_request
    resp = await self._pool.handle_async_request(req)
           ^^^^^^^^^^^^^^^^^^^^^^^^^^^^^^^^^^^^^^^^^^
  File "/mnt/c/Users/Andrew/Documents/freegenai/opea-comps-w3/venv/lib/python3.12/site-packages/httpcore/_async/connection_pool.py", line 256, in handle_async_request
    raise exc from None
  File "/mnt/c/Users/Andrew/Documents/freegenai/opea-comps-w3/venv/lib/python3.12/site-packages/httpcore/_async/connection_pool.py", line 236, in handle_async_request
    response = await connection.handle_async_request(
               ^^^^^^^^^^^^^^^^^^^^^^^^^^^^^^^^^^^^^^
  File "/mnt/c/Users/Andrew/Documents/freegenai/opea-comps-w3/venv/lib/python3.12/site-packages/httpcore/_async/connection.py", line 101, in handle_async_request
    raise exc
  File "/mnt/c/Users/Andrew/Documents/freegenai/opea-comps-w3/venv/lib/python3.12/site-packages/httpcore/_async/connection.py", line 78, in handle_async_request
    stream = await self._connect(request)
             ^^^^^^^^^^^^^^^^^^^^^^^^^^^^
  File "/mnt/c/Users/Andrew/Documents/freegenai/opea-comps-w3/venv/lib/python3.12/site-packages/httpcore/_async/connection.py", line 124, in _connect
    stream = await self._network_backend.connect_tcp(**kwargs)
             ^^^^^^^^^^^^^^^^^^^^^^^^^^^^^^^^^^^^^^^^^^^^^^^^^
  File "/mnt/c/Users/Andrew/Documents/freegenai/opea-comps-w3/venv/lib/python3.12/site-packages/httpcore/_backends/auto.py", line 31, in connect_tcp
    return await self._backend.connect_tcp(
           ^^^^^^^^^^^^^^^^^^^^^^^^^^^^^^^^
  File "/mnt/c/Users/Andrew/Documents/freegenai/opea-comps-w3/venv/lib/python3.12/site-packages/httpcore/_backends/anyio.py", line 113, in connect_tcp
    with map_exceptions(exc_map):
  File "/usr/lib/python3.12/contextlib.py", line 158, in __exit__
    self.gen.throw(value)
  File "/mnt/c/Users/Andrew/Documents/freegenai/opea-comps-w3/venv/lib/python3.12/site-packages/httpcore/_exceptions.py", line 14, in map_exceptions
    raise to_exc(exc) from exc
httpcore.ConnectError: [Errno -3] Temporary failure in name resolution

The above exception was the direct cause of the following exception:

Traceback (most recent call last):
  File "/mnt/c/Users/Andrew/Documents/freegenai/opea-comps-w3/MegaService/server.py", line 313, in megaservice
    llm_response = await llm_client.post(
                   ^^^^^^^^^^^^^^^^^^^^^^
  File "/mnt/c/Users/Andrew/Documents/freegenai/opea-comps-w3/venv/lib/python3.12/site-packages/httpx/_client.py", line 1859, in post
    return await self.request(
           ^^^^^^^^^^^^^^^^^^^
  File "/mnt/c/Users/Andrew/Documents/freegenai/opea-comps-w3/venv/lib/python3.12/site-packages/httpx/_client.py", line 1540, in request
    return await self.send(request, auth=auth, follow_redirects=follow_redirects)
           ^^^^^^^^^^^^^^^^^^^^^^^^^^^^^^^^^^^^^^^^^^^^^^^^^^^^^^^^^^^^^^^^^^^^^^
  File "/mnt/c/Users/Andrew/Documents/freegenai/opea-comps-w3/venv/lib/python3.12/site-packages/httpx/_client.py", line 1629, in send
    response = await self._send_handling_auth(
               ^^^^^^^^^^^^^^^^^^^^^^^^^^^^^^^
  File "/mnt/c/Users/Andrew/Documents/freegenai/opea-comps-w3/venv/lib/python3.12/site-packages/httpx/_client.py", line 1657, in _send_handling_auth
    response = await self._send_handling_redirects(
               ^^^^^^^^^^^^^^^^^^^^^^^^^^^^^^^^^^^^
  File "/mnt/c/Users/Andrew/Documents/freegenai/opea-comps-w3/venv/lib/python3.12/site-packages/httpx/_client.py", line 1694, in _send_handling_redirects
    response = await self._send_single_request(request)
               ^^^^^^^^^^^^^^^^^^^^^^^^^^^^^^^^^^^^^^^^
  File "/mnt/c/Users/Andrew/Documents/freegenai/opea-comps-w3/venv/lib/python3.12/site-packages/httpx/_client.py", line 1730, in _send_single_request
    response = await transport.handle_async_request(request)
               ^^^^^^^^^^^^^^^^^^^^^^^^^^^^^^^^^^^^^^^^^^^^^
  File "/mnt/c/Users/Andrew/Documents/freegenai/opea-comps-w3/venv/lib/python3.12/site-packages/httpx/_transports/default.py", line 393, in handle_async_request
    with map_httpcore_exceptions():
  File "/usr/lib/python3.12/contextlib.py", line 158, in __exit__
    self.gen.throw(value)
  File "/mnt/c/Users/Andrew/Documents/freegenai/opea-comps-w3/venv/lib/python3.12/site-packages/httpx/_transports/default.py", line 118, in map_httpcore_exceptions
    raise mapped_exc(message) from exc
httpx.ConnectError: [Errno -3] Temporary failure in name resolution
2025-04-12 09:27:04 [INFO] llm: [req_1744414024] Sending LLM request
2025-04-12 09:27:04 [INFO] llm: [req_1744414024] Sending LLM request
2025-04-12 09:27:09 [INFO] llm: [req_1744414024] Got LLM response: 你好，我很好，谢谢。...
2025-04-12 09:27:09 [INFO] llm: [req_1744414024] Got LLM response: 你好，我很好，谢谢。...
2025-04-12 09:32:15 [INFO] llm: [req_1744414335] Sending LLM request
2025-04-12 09:32:15 [INFO] llm: [req_1744414335] Sending LLM request
2025-04-12 09:32:17 [INFO] llm: [req_1744414335] Got LLM response: 你好！我很好，谢谢。...
2025-04-12 09:32:17 [INFO] llm: [req_1744414335] Got LLM response: 你好！我很好，谢谢。...
